Workbook

Sheet Instrucciones
A1: PLANTILLA DE ESTUDIO DE RENOVACIÓN ELÉCTRICA
A2: Datos de entrada para la aplicación de estudios de renovación — v2
B4: CÓMO RELLENAR ESTA PLANTILLA
B5: 1. Hoja CLIENTE: datos generales del cliente y del gestor que solicita el estudio.
B6: 2. Hoja SUMINISTROS: una fila por punto de suministro (CUPS), hasta 50. Incluya potencias contratadas,
B7: condiciones actuales del contrato (precios de energía y potencia) y si dichos precios incluyen peajes y cargos.
B8: 3. Hoja CONSUMOS: para cada CUPS, los kWh mensuales por periodo de los últimos 12 meses.
B10: NOTAS IMPORTANTES
B11: • Solo son editables las celdas con texto en AZUL. El resto de la hoja está protegido (sin contraseña).
B12: • Tarifas admitidas: 2.0TD, 3.0TD, 6.1TD, 6.2TD, 6.3TD y 6.4TD.
B13: • En tarifa 2.0TD utilice solo P1–P3 en energía y P1–P2 en potencia; deje el resto de periodos vacíos.
B14: • Los precios actuales se introducen en €/kWh (energía) y €/kW·año (potencia), sin IVA.
B15: • POTENCIA SEGÚN ATR: si el contrato actual factura la potencia al precio regulado (peajes + cargos), marque Sí
B16: en la columna '¿Precio según ATR?' y no rellene los precios de potencia (se sombrearán en gris):
... B23: Ejemplo de celda editable

Sheet Cliente
A1: DATOS DEL CLIENTE
A2: Cumplimente todos los campos. Celdas editables en azul.
B4: Razón social
B5: CIF / NIF
B6: Dirección fiscal
B7: Gestor solicitante del estudio
B8: Email del gestor

Sheet Suministros
A1: PUNTOS DE SUMINISTRO Y CONDICIONES ACTUALES
A2: Una fila por CUPS (máx. 50). Precios sin IVA. En 2.0TD: energía P1–P3 y potencia P1–P2.
A3: DATOS DEL PUNTO DE SUMINISTRO | G3: POTENCIAS CONTRATADAS (kW) | M3: CONTRATO ACTUAL | Q3: PRECIO ENERGÍA ACTUAL (€/kWh) | W3: PRECIO POTENCIA ACTUAL (€/kW·año)
A4: Nº | B4: Titular contrato | C4: CIF | D4: CUPS | E4: Dirección del suministro | F4: Tarifa de acceso | G4: P1 | H4: P2 | I4: P3 | J4: P4 | K4: P5 | L4: P6 | M4: Comercializadora actual | N4: Modalidad actual | O4: Fecha fin contrato | P4: ¿Peajes y cargos incluidos en precio de energía? | Q4: P1 | R4: P2 | S4: P3 | T4: P4 | U4: P5 | V4: P6 | W4: ¿Precio según ATR? (Sí/No) | X4: P1 | Y4: P2 | Z4: P3 | AA4: P4 | AB4: P5 | AC4: P6
A5: 1
A6: 2
A7: 3
A8: 4
A9: 5
A10: 6
A11: 7
A12: 8
A13: 9
A14: 10
A15: 11
A16: 12
... A54: 50

Sheet Consumos
A1: CONSUMOS MENSUALES POR PERIODO (kWh)
A2: Últimos 12 meses por CUPS. El CUPS se muestra automáticamente desde la hoja SUMINISTROS.
A4: SUMINISTRO 1 | C4: =IF(Suministros!D5="","(sin CUPS — rellene la hoja Suministros)",Suministros!D5) -> (sin CUPS — rellene la hoja Suministros)
A5: Mes | B5: Año | C5: P1 | D5: P2 | E5: P3 | F5: P4 | G5: P5 | H5: P6 | I5: Total (kWh)
A6: Enero | I6: =IF(COUNT(C6:H6)=0,"",SUM(C6:H6))
A7: Febrero | I7: =IF(COUNT(C7:H7)=0,"",SUM(C7:H7))
A8: Marzo | I8: =IF(COUNT(C8:H8)=0,"",SUM(C8:H8))
A9: Abril | I9: =IF(COUNT(C9:H9)=0,"",SUM(C9:H9))
A10: Mayo | I10: =IF(COUNT(C10:H10)=0,"",SUM(C10:H10))
A11: Junio | I11: =IF(COUNT(C11:H11)=0,"",SUM(C11:H11))
A12: Julio | I12: =IF(COUNT(C12:H12)=0,"",SUM(C12:H12))
A13: Agosto | I13: =IF(COUNT(C13:H13)=0,"",SUM(C13:H13))
A14: Septiembre | I14: =IF(COUNT(C14:H14)=0,"",SUM(C14:H14))
A15: Octubre | I15: =IF(COUNT(C15:H15)=0,"",SUM(C15:H15))
A16: Noviembre | I16: =IF(COUNT(C16:H16)=0,"",SUM(C16:H16))
A17: Diciembre | I17: =IF(COUNT(C17:H17)=0,"",SUM(C17:H17))
A18: TOTAL | C18: =IF(COUNT(C6:C17)=0,"",SUM(C6:C17)) | D18: =IF(COUNT(D6:D17)=0,"",SUM(D6:D17)) | E18: =IF(COUNT(E6:E17)=0,"",SUM(E6:E17)) | F18: =IF(COUNT(F6:F17)=0,"",SUM(F6:F17)) | G18: =IF(COUNT(G6:G17)=0,"",SUM(G6:G17)) | H18: =IF(COUNT(H6:H17)=0,"",SUM(H6:H17)) | I18: =IF(COUNT(I6:I17)=0,"",SUM(I6:I17))
A22: SUMINISTRO 2 | C22: =IF(Suministros!D6="","(sin CUPS — rellene la hoja Suministros)",Suministros!D6) -> (sin CUPS — rellene la hoja Suministros)
A23: Mes | B23: Año | C23: P1 | D23: P2 | E23: P3 | F23: P4 | G23: P5 | H23: P6 | I23: Total (kWh)
A24: Enero | I24: =IF(COUNT(C24:H24)=0,"",SUM(C24:H24))
A25: Febrero | I25: =IF(COUNT(C25:H25)=0,"",SUM(C25:H25))
A26: Marzo | I26: =IF(COUNT(C26:H26)=0,"",SUM(C26:H26))
A27: Abril | I27: =IF(COUNT(C27:H27)=0,"",SUM(C27:H27))
A28: Mayo | I28: =IF(COUNT(C28:H28)=0,"",SUM(C28:H28))
A29: Junio | I29: =IF(COUNT(C29:H29)=0,"",SUM(C29:H29))
A30: Julio | I30: =IF(COUNT(C30:H30)=0,"",SUM(C30:H30))
A31: Agosto | I31: =IF(COUNT(C31:H31)=0,"",SUM(C31:H31))
A32: Septiembre | I32: =IF(COUNT(C32:H32)=0,"",SUM(C32:H32))
A33: Octubre | I33: =IF(COUNT(C33:H33)=0,"",SUM(C33:H33))
A34: Noviembre | I34: =IF(COUNT(C34:H34)=0,"",SUM(C34:H34))
A35: Diciembre | I35: =IF(COUNT(C35:H35)=0,"",SUM(C35:H35))
A36: TOTAL | C36: =IF(COUNT(C24:C35)=0,"",SUM(C24:C35)) | D36: =IF(COUNT(D24:D35)=0,"",SUM(D24:D35)) | E36: =IF(COUNT(E24:E35)=0,"",SUM(E24:E35)) | F36: =IF(COUNT(F24:F35)=0,"",SUM(F24:F35)) | G36: =IF(COUNT(G24:G35)=0,"",SUM(G24:G35)) | H36: =IF(COUNT(H24:H35)=0,"",SUM(H24:H35)) | I36: =IF(COUNT(I24:I35)=0,"",SUM(I24:I35))
A40: SUMINISTRO 3 | C40: =IF(Suministros!D7="","(sin CUPS — rellene la hoja Suministros)",Suministros!D7) -> (sin CUPS — rellene la hoja Suministros)
A41: Mes | B41: Año | C41: P1 | D41: P2 | E41: P3 | F41: P4 | G41: P5 | H41: P6 | I41: Total (kWh)
A42: Enero | I42: =IF(COUNT(C42:H42)=0,"",SUM(C42:H42))
A43: Febrero | I43: =IF(COUNT(C43:H43)=0,"",SUM(C43:H43))
A44: Marzo | I44: =IF(COUNT(C44:H44)=0,"",SUM(C44:H44))
A45: Abril | I45: =IF(COUNT(C45:H45)=0,"",SUM(C45:H45))
A46: Mayo | I46: =IF(COUNT(C46:H46)=0,"",SUM(C46:H46))
A47: Junio | I47: =IF(COUNT(C47:H47)=0,"",SUM(C47:H47))
...
